numprocs=10
Traceback (most recent call last):
  File "/home/people/22213094/CBG_Model_Fleming_PTS/Cortex_BasalGanglia_DBS_model/./run_model.py", line 68, in <module>
    c = Config(args.config_file)
  File "/home/people/22213094/CBG_Model_Fleming_PTS/Cortex_BasalGanglia_DBS_model/config.py", line 85, in __init__
    with self.config_file.open("r") as f:
  File "/opt/software/python/3.9.15-with-shared/lib/python3.9/pathlib.py", line 1252, in open
    return io.open(self, mode, buffering, encoding, errors, newline,
  File "/opt/software/python/3.9.15-with-shared/lib/python3.9/pathlib.py", line 1120, in _opener
    return self._accessor.open(self, flags, mode)
FileNotFoundError: [Errno 2] No such file or directory: '/home/people/22213094/CBG_Model_Fleming_PTS/configs/pts_test_0.yml'
Traceback (most recent call last):
  File "/home/people/22213094/CBG_Model_Fleming_PTS/Cortex_BasalGanglia_DBS_model/./run_model.py", line 68, in <module>
    c = Config(args.config_file)
  File "/home/people/22213094/CBG_Model_Fleming_PTS/Cortex_BasalGanglia_DBS_model/config.py", line 85, in __init__
    with self.config_file.open("r") as f:
  File "/opt/software/python/3.9.15-with-shared/lib/python3.9/pathlib.py", line 1252, in open
    return io.open(self, mode, buffering, encoding, errors, newline,
  File "/opt/software/python/3.9.15-with-shared/lib/python3.9/pathlib.py", line 1120, in _opener
    return self._accessor.open(self, flags, mode)
FileNotFoundError: [Errno 2] No such file or directory: '/home/people/22213094/CBG_Model_Fleming_PTS/configs/pts_test_0.yml'
Traceback (most recent call last):
  File "/home/people/22213094/CBG_Model_Fleming_PTS/Cortex_BasalGanglia_DBS_model/./run_model.py", line 68, in <module>
    c = Config(args.config_file)
  File "/home/people/22213094/CBG_Model_Fleming_PTS/Cortex_BasalGanglia_DBS_model/config.py", line 85, in __init__
    with self.config_file.open("r") as f:
  File "/opt/software/python/3.9.15-with-shared/lib/python3.9/pathlib.py", line 1252, in open
    return io.open(self, mode, buffering, encoding, errors, newline,
  File "/opt/software/python/3.9.15-with-shared/lib/python3.9/pathlib.py", line 1120, in _opener
    return self._accessor.open(self, flags, mode)
FileNotFoundError: [Errno 2] No such file or directory: '/home/people/22213094/CBG_Model_Fleming_PTS/configs/pts_test_0.yml'
Traceback (most recent call last):
  File "/home/people/22213094/CBG_Model_Fleming_PTS/Cortex_BasalGanglia_DBS_model/./run_model.py", line 68, in <module>
    c = Config(args.config_file)
  File "/home/people/22213094/CBG_Model_Fleming_PTS/Cortex_BasalGanglia_DBS_model/config.py", line 85, in __init__
    with self.config_file.open("r") as f:
  File "/opt/software/python/3.9.15-with-shared/lib/python3.9/pathlib.py", line 1252, in open
    return io.open(self, mode, buffering, encoding, errors, newline,
  File "/opt/software/python/3.9.15-with-shared/lib/python3.9/pathlib.py", line 1120, in _opener
    return self._accessor.open(self, flags, mode)
FileNotFoundError: [Errno 2] No such file or directory: '/home/people/22213094/CBG_Model_Fleming_PTS/configs/pts_test_0.yml'
Traceback (most recent call last):
  File "/home/people/22213094/CBG_Model_Fleming_PTS/Cortex_BasalGanglia_DBS_model/./run_model.py", line 68, in <module>
    c = Config(args.config_file)
  File "/home/people/22213094/CBG_Model_Fleming_PTS/Cortex_BasalGanglia_DBS_model/config.py", line 85, in __init__
    with self.config_file.open("r") as f:
  File "/opt/software/python/3.9.15-with-shared/lib/python3.9/pathlib.py", line 1252, in open
    return io.open(self, mode, buffering, encoding, errors, newline,
  File "/opt/software/python/3.9.15-with-shared/lib/python3.9/pathlib.py", line 1120, in _opener
    return self._accessor.open(self, flags, mode)
FileNotFoundError: [Errno 2] No such file or directory: '/home/people/22213094/CBG_Model_Fleming_PTS/configs/pts_test_0.yml'
Traceback (most recent call last):
  File "/home/people/22213094/CBG_Model_Fleming_PTS/Cortex_BasalGanglia_DBS_model/./run_model.py", line 68, in <module>
    c = Config(args.config_file)
  File "/home/people/22213094/CBG_Model_Fleming_PTS/Cortex_BasalGanglia_DBS_model/config.py", line 85, in __init__
    with self.config_file.open("r") as f:
  File "/opt/software/python/3.9.15-with-shared/lib/python3.9/pathlib.py", line 1252, in open
    return io.open(self, mode, buffering, encoding, errors, newline,
  File "/opt/software/python/3.9.15-with-shared/lib/python3.9/pathlib.py", line 1120, in _opener
    return self._accessor.open(self, flags, mode)
FileNotFoundError: [Errno 2] No such file or directory: '/home/people/22213094/CBG_Model_Fleming_PTS/configs/pts_test_0.yml'
Traceback (most recent call last):
  File "/home/people/22213094/CBG_Model_Fleming_PTS/Cortex_BasalGanglia_DBS_model/./run_model.py", line 68, in <module>
    c = Config(args.config_file)
  File "/home/people/22213094/CBG_Model_Fleming_PTS/Cortex_BasalGanglia_DBS_model/config.py", line 85, in __init__
    with self.config_file.open("r") as f:
  File "/opt/software/python/3.9.15-with-shared/lib/python3.9/pathlib.py", line 1252, in open
    return io.open(self, mode, buffering, encoding, errors, newline,
  File "/opt/software/python/3.9.15-with-shared/lib/python3.9/pathlib.py", line 1120, in _opener
    return self._accessor.open(self, flags, mode)
FileNotFoundError: [Errno 2] No such file or directory: '/home/people/22213094/CBG_Model_Fleming_PTS/configs/pts_test_0.yml'
Traceback (most recent call last):
  File "/home/people/22213094/CBG_Model_Fleming_PTS/Cortex_BasalGanglia_DBS_model/./run_model.py", line 68, in <module>
    c = Config(args.config_file)
  File "/home/people/22213094/CBG_Model_Fleming_PTS/Cortex_BasalGanglia_DBS_model/config.py", line 85, in __init__
    with self.config_file.open("r") as f:
  File "/opt/software/python/3.9.15-with-shared/lib/python3.9/pathlib.py", line 1252, in open
    return io.open(self, mode, buffering, encoding, errors, newline,
  File "/opt/software/python/3.9.15-with-shared/lib/python3.9/pathlib.py", line 1120, in _opener
    return self._accessor.open(self, flags, mode)
FileNotFoundError: [Errno 2] No such file or directory: '/home/people/22213094/CBG_Model_Fleming_PTS/configs/pts_test_0.yml'
Traceback (most recent call last):
  File "/home/people/22213094/CBG_Model_Fleming_PTS/Cortex_BasalGanglia_DBS_model/./run_model.py", line 68, in <module>
    c = Config(args.config_file)
  File "/home/people/22213094/CBG_Model_Fleming_PTS/Cortex_BasalGanglia_DBS_model/config.py", line 85, in __init__
    with self.config_file.open("r") as f:
  File "/opt/software/python/3.9.15-with-shared/lib/python3.9/pathlib.py", line 1252, in open
    return io.open(self, mode, buffering, encoding, errors, newline,
  File "/opt/software/python/3.9.15-with-shared/lib/python3.9/pathlib.py", line 1120, in _opener
    return self._accessor.open(self, flags, mode)
FileNotFoundError: [Errno 2] No such file or directory: '/home/people/22213094/CBG_Model_Fleming_PTS/configs/pts_test_0.yml'
Traceback (most recent call last):
  File "/home/people/22213094/CBG_Model_Fleming_PTS/Cortex_BasalGanglia_DBS_model/./run_model.py", line 68, in <module>
    c = Config(args.config_file)
  File "/home/people/22213094/CBG_Model_Fleming_PTS/Cortex_BasalGanglia_DBS_model/config.py", line 85, in __init__
    with self.config_file.open("r") as f:
  File "/opt/software/python/3.9.15-with-shared/lib/python3.9/pathlib.py", line 1252, in open
    return io.open(self, mode, buffering, encoding, errors, newline,
  File "/opt/software/python/3.9.15-with-shared/lib/python3.9/pathlib.py", line 1120, in _opener
    return self._accessor.open(self, flags, mode)
FileNotFoundError: [Errno 2] No such file or directory: '/home/people/22213094/CBG_Model_Fleming_PTS/configs/pts_test_0.yml'
--------------------------------------------------------------------------
Primary job  terminated normally, but 1 process returned
a non-zero exit code. Per user-direction, the job has been aborted.
--------------------------------------------------------------------------
--------------------------------------------------------------------------
mpirun detected that one or more processes exited with non-zero status, thus causing
the job to be terminated. The first process to do so was:

  Process name: [[34868,1],1]
  Exit code:    1
--------------------------------------------------------------------------
